Workbook

Sheet README
B2: SoFi Technologies, Inc. (NASDAQ: SOFI)
B3: Equity valuation model: residual income
B5: Prepared by | C5: Ashley Mone · August 2026
B6: Purpose | C6: Values SoFi under a bank lens and a fintech lens to test which framework the market is applying.
B8: Sources | C8: SoFi 2025 Form 10-K; Q4 2025 and Q2 2026 earnings releases and call transcript.
C9: Peer figures from Q2 2026 company filings. Market data as of August 10, 2026.
C10: Risk-free rate: FRED (DGS10). Equity risk premium: Damodaran implied ERP, 2026.
B12: Legend | C12: Blue = input · Black = formula · Green = link to another tab · n/a = not applicable
B14: Contents | C14: 1 Historicals: reported figures, FY2023 to FY2025
C15: 2 Assumptions: forecast drivers, each with sourced reasoning
C16: 3 Projections: 2026E to 2028E, with checks against management guidance
C17: 4 Valuation: residual income, terminal value, reverse test
C18: 5 Bank comparables
C19: 6 Fintech comparables
C20: 7 Sensitivity and bear / base / bull scenarios
B22: Key assumptions | C22: Cost of equity 14.00% (beta 2.20). Terminal ROTCE 20%, the low end of management's 20-30% target.
C23: 2026 revenue forecast runs 3.9% above the top of management's guidance range, deliberately.
B25: Conclusion | C25: Value per share $10.18 vs. market $18.38. At the current price the market implies ~29% long-run
C26: return on tangible common equity; this forecast reaches 13.3% by 2028.
B28: A standard DCF is not used: a growing lender consumes cash, so free cash flow understates value.

Sheet 1. Historicals
B2: TAB 1: HISTORICAL FINANCIALS
B3: All numbers in $ thousands, exactly as the 10-K reports them.
B5: Line item | C5: FY2023 | D5: FY2024 | E5: FY2025 | F5: Source (page + statement)
B6: INCOME STATEMENT (10-K p.149)
B7: Net interest income | C7: 1261740 | D7: 1716481 | E7: 2218956
B8: Total noninterest income | C8: 861049 | D8: 958378 | E8: 1394398
B9: Total net revenue | C9: =SUM(C7:C8) -> 2122789 | D9: =SUM(D7:D8) -> 2674859 | E9: =SUM(E7:E8) -> 3613354
B10: Provision for credit losses | C10: 54945 | D10: 31712 | E10: 30319
B11: Total noninterest expense | C11: 2369002 | D11: 2409802 | E11: 3057178
B12: Net income (loss) | C12: -300742 | D12: 498665 | E12: 481320
B14: BALANCE SHEET (10-K p.147)
B15: Total deposits | D15: 25978204 | E15: 37505395
B16: Loans held for sale | D16: 17684892 | E16: 22862749
B17: Loans held for investment, fair value | D17: 8597368 | E17: 13657578
B18: Loans held for investment, amortized cost | D18: 1246458 | E18: 1516736
B19: Total assets | D19: 36250951 | E19: 50660478
B20: Total liabilities | D20: 29725817 | E20: 40170983
B21: Total permanent equity | D21: 6525134 | E21: 10489495
B23: KEY RATIOS (p.94: check, don't guess)
B24: Net interest margin | C24: 0.0588 | D24: 0.058 | E24: 0.0585
B25: Total risk-based capital ratio (SoFi Bank) | D25: 0.175 | E25: 0.166
B27: CASH FLOW (10-K p.151)
B28: Net cash from operating activities | C28: -7227139 | D28: -1119807 | E28: -3742458
B29: Net cash from investing activities | C29: -1889864 | D29: -4820990 | E29: -6719107
B30: Net cash from financing activities | C30: 10885602 | D30: 5034577 | E30: 13109333
B33: Net interest income | E33: 2218956 | F33: 2025 10-K, p.94, Selected Financial Data
B39: H1 2026 REFERENCE
B40: Evidence supporting the Tab 2 assumptions. H1 = first half (Jan-Jun).
B42: Line item | C42: H1 2025 | D42: H1 2026 | E42: % change | F42: Source
B43: Total net revenue | C43: 1626703 | D43: 2319044 | E43: =D43/C43-1 -> 0.42560996 | F43: Q2'26 release, Table 1, p.14
B44: Net interest income | C44: 1016563 | D44: 1481183 | E44: =D44/C44-1 -> 0.45704988 | F44: Q2'26 release, Table 1, p.14
B45: Total noninterest income | C45: 610140 | D45: 837861 | E45: =D45/C45-1 -> 0.37322746 | F45: Q2'26 release, Table 1, p.14
B46: Total noninterest expense | C46: 1419016 | D46: 1892533 | E46: =D46/C46-1 -> 0.33369391 | F46: Q2'26 release, Table 1, p.14
B47: Net income | C47: 168379 | D47: 323323 | E47: =D47/C47-1 -> 0.92020976 | F47: Q2'26 release, Table 1, p.14
B48: Net interest margin | C48: 0.0594 | D48: 0.0594 | E48: =D48/C48-1 -> 0 | F48: Q2'26 release, Table 4, p.23
B50: BALANCE SHEET SNAPSHOT (point in time, not a period)
C51: Dec 31, 2025 | D51: Jun 30, 2026 | E51: % change
B52: Total deposits | C52: 37505395 | D52: 45543160 | E52: =D52/C52-1 -> 0.21430957 | F52: Q2'26 release, Table 3, p.21
B53: Loans held for sale | C53: 22862749 | D53: 29737289 | E53: =D53/C53-1 -> 0.30068738 | F53: Q2'26 release, Table 3, p.21
B54: Loans held for investment, FV | C54: 13657578 | D54: 16920564 | E54: =D54/C54-1 -> 0.23891396 | F54: Q2'26 release, Table 3, p.21
...

Sheet 2. Assumptions
B2: TAB 2: FORECAST ASSUMPTIONS
B3: Every assumption on this tab carries a stated reason in the Why column.
B5: Driver | C5: 2026E | D5: 2027E | E5: 2028E | F5: Why
B6: Deposit growth rate | C6: 0.38 | D6: 0.28 | E6: 0.22 | F6: Deposits grew 44% in 2025 to $37.5B. But half of 2026 has already happened: deposits reached $45.5B by June 30, up 21% in six months alone. If the second half adds a similar amount, full-year growth lands near 38-40%. Management is deliberately funding loans on the balance sheet to lock in visible future interest income, which keeps deposit gathering a priority. I use 38% to allow for slight second-half deceleration as the base grows.
B7: Loan growth rate | C7: 0.4 | D7: 0.3 | E7: 0.24 | F7: SoFi's loan book grew 26% in just the first six months of 2026, from $38.0B to $47.9B, after growing 38% in all of 2025. Management is deliberately keeping more loans on its own books instead of selling them to partners, because loans it holds generate predictable interest income for years. I use 40% for the full year. Note that loans are growing faster than deposits, so SoFi is borrowing to cover the difference, its debt rose from $1.8B to $3.3B in the same six months.
B8: Net interest margin | C8: 0.0595 | D8: 0.059 | E8: 0.058 | F8: SoFi's margin has been remarkably stable (5.80% in 2024, 5.85% in 2025), and is rising in 2026: 5.94% in the first half and 5.98% in Q2, up from 5.86% a year earlier. Two things support it. Management now expects 1-2 rate hikes in 2026 rather than the cuts they originally assumed, which helps the rates SoFi earns on loans. And the CFO has said they expect margin to stay above 5% for the foreseeable future.
B9: Noninterest income growth | C9: 0.35 | D9: 0.3 | E9: 0.26 | F9: Noninterest income grew 37% in the first half of 2026 (actual, per Q2 release), versus 45% for full-year 2025. I assume modest deceleration in the second half as the base scales, giving 35% for the full year, consistent with management's raised guidance of 32-35% total revenue growth.
B10: Noninterest expense growth | C10: 0.32 | D10: 0.26 | E10: 0.21 | F10: SoFi's costs grew 33% in the first half of 2026, faster than the 27% in 2025, because management is spending heavily on new products launched this year, big business banking, small business loans, crypto, and SoFi Plus. The CFO said they'd rather invest in growth now than report higher profits, which is why they raised their revenue target but kept their profit target unchanged. Importantly, costs are still growing slower than revenue (33% vs 43%), so the company is getting more profitable, not less.
B11: Provision as % of loans | C11: 0.0008 | D11: 0.0008 | E11: 0.0008 | F11: SoFi's provision expense was only $30M in 2025 against a $38B loan book, which looks impossibly low for consumer lending. The reason is how the loans are recorded. Most of SoFi's loans are carried at their current market value and re-priced every quarter, so expected losses are already reflected in the loan's value and never appear as a separate expense. Only about $1.3B of the $47.9B loan book is recorded the other way, where losses do run through this line. That's why the number is so small. SoFi's actual credit losses show up in its charge-off figures instead: personal loans were charged off at 2.62% in Q2 2026, an improvement from 2.83% a year earlier
B12: Effective tax rate | C12: 0.22 | D12: 0.22 | E12: 0.22 | F12: 22%. SoFi's management said they expect to pay about 22% of their profits in taxes for 2026, higher than they originally planned. I use their number instead of looking at what they paid in past years, because those years were distorted by a one-time tax benefit in 2024 that made their tax rate look artificially low. I keep 22% for 2027 and 2028 since there's no reason to expect it to change.
B14: DISCOUNT RATE INPUTS
B15: Risk-free rate (10-yr UST) | C15: 0.0469 | F15: FRED DGS10, retrieved Aug 10 2026
B16: Equity risk premium | C16: 0.0423 | F16: Damodaran implied ERP, start of 2026 (pages.stern.nyu.edu/adamodar)
B17: Beta | C17: 2.2 | F17: Yahoo Finance, 5-year monthly. Published betas range ~1.8-2.6 by methodology.
B18: Cost of equity | C18: =C15+C17*C16 -> 0.13996
B19: Terminal growth rate | C19: 0.04 | F19: Long-run nominal GDP growth/ terminal growth cap
B21: Note: for a bank, value equity directly (cost of equity), not the whole firm via WACC.
B22: Debt is a bank's raw material, not its financing, which is why this model values equity directly rather than the firm.

Sheet 3. Projections
B2: TAB 3: PROJECTED FINANCIALS
B3: Every cell is a formula. Base year links to Tab 1, growth comes from Tab 2. Nothing is typed here.
B5: Line item | C5: FY2025A | D5: 2026E | E5: 2027E | F5: 2028E | G5: How it's built
B6: BALANCE SHEET DRIVERS
B7: Total deposits | C7: ='1. Historicals'!E15 -> 37505395 | D7: =C7*(1+'2. Assumptions'!C6) -> 51757445 | E7: =D7*(1+'2. Assumptions'!D6) -> 66249530 | F7: =E7*(1+'2. Assumptions'!E6) -> 80824426 | G7: Prior year x (1 + deposit growth), Tab 2 row 6
B8: Total loans (period end) | C8: =SUM('1. Historicals'!E16:E18) -> 38037063 | D8: =C8*(1+'2. Assumptions'!C7) -> 53251888 | E8: =D8*(1+'2. Assumptions'!D7) -> 69227455 | F8: =E8*(1+'2. Assumptions'!E7) -> 85842044 | G8: Prior year x (1 + loan growth), Tab 2 row 7
B9: Average interest-earning assets | C9: 37913495 | D9: =C9*(1+'2. Assumptions'!C7) -> 53078893 | E9: =D9*(1+'2. Assumptions'!D7) -> 69002561 | F9: =E9*(1+'2. Assumptions'!E7) -> 85563176 | G9: Grows with loans. 2025A actual from Q2'26 release, Table 4, p.23
B11: INCOME STATEMENT
B12: Net interest income | C12: ='1. Historicals'!E7 -> 2218956 | D12: =D9*'2. Assumptions'!C8 -> 3158194.1 | E12: =E9*'2. Assumptions'!D8 -> 4071151.1 | F12: =F9*'2. Assumptions'!E8 -> 4962664.2 | G12: Average interest-earning assets x net interest margin
B13: Total noninterest income | C13: ='1. Historicals'!E8 -> 1394398 | D13: =C13*(1+'2. Assumptions'!C9) -> 1882437.3 | E13: =D13*(1+'2. Assumptions'!D9) -> 2447168.5 | F13: =E13*(1+'2. Assumptions'!E9) -> 3083432.3 | G13: Prior year x (1 + noninterest income growth)
B14: Total net revenue | C14: ='1. Historicals'!E9 -> 3613354 | D14: =D12+D13 -> 5040631.4 | E14: =E12+E13 -> 6518319.6 | F14: =F12+F13 -> 8046096.5 | G14: Net interest income + noninterest income
B15: Provision for credit losses | C15: ='1. Historicals'!E10 -> 30319 | D15: =D8*'2. Assumptions'!C11 -> 42601.511 | E15: =E8*'2. Assumptions'!D11 -> 55381.964 | F15: =F8*'2. Assumptions'!E11 -> 68673.635 | G15: Total loans x provision rate
B16: Total noninterest expense | C16: ='1. Historicals'!E11 -> 3057178 | D16: =C16*(1+'2. Assumptions'!C10) -> 4035475 | E16: =D16*(1+'2. Assumptions'!D10) -> 5084698.4 | F16: =E16*(1+'2. Assumptions'!E10) -> 6152485.1 | G16: Prior year x (1 + expense growth)
B17: Pre-tax income | C17: =C14-C15-C16 -> 525857 | D17: =D14-D15-D16 -> 962554.96 | E17: =E14-E15-E16 -> 1378239.2 | F17: =F14-F15-F16 -> 1824937.7 | G17: Revenue less provision less expense
B18: Income tax expense | C18: 44537 | D18: =D17*'2. Assumptions'!C12 -> 211762.09 | E18: =E17*'2. Assumptions'!D12 -> 303212.62 | F18: =F17*'2. Assumptions'!E12 -> 401486.3 | G18: Pre-tax income x effective tax rate
B19: Net income | C19: ='1. Historicals'!E12 -> 481320 | D19: =D17-D18 -> 750792.87 | E19: =E17-E18 -> 1075026.6 | F19: =F17-F18 -> 1423451.4 | G19: Pre-tax income less tax
B21: CHECKS: these should hold after any change to an assumption
B22: Revenue growth | D22: =D14/C14-1 -> 0.39500072 | E22: =E14/D14-1 -> 0.29315537 | F22: =F14/E14-1 -> 0.23438202 | G22: Blank for 2025A: needs 2024 revenue, which is on Tab 1, not this tab.
B23: Net income margin | C23: =C19/C14 -> 0.13320588 | D23: =D19/D14 -> 0.14894818 | E23: =E19/E14 -> 0.16492388 | F23: =F19/F14 -> 0.17691205
B24: Expense growth vs revenue growth | D24: =(D16/C16-1)-(D14/C14-1) -> -0.075000721 | E24: =(E16/D16-1)-(E14/D14-1) -> -0.033155365 | F24: =(F16/E16-1)-(F14/E14-1) -> -0.024382017 | G24: Negative = costs growing slower than revenue = margins expanding
B25: Return on tangible common equity | D25: =IFERROR(D19/'4. Valuation'!D22,"") -> 0.084281892 | E25: =IFERROR(E19/'4. Valuation'!E22,"") -> 0.11129896 | F25: =IFERROR(F19/'4. Valuation'!F22,"") -> 0.13261226 | G25: Blank for 2025A: needs beginning-2025 tangible book value, which the model does not carry.
B27: GUIDANCE CHECK: does the model agree with management?
B28: Model total net revenue, 2026E | D28: =D14 -> 5040631.4
B29: Management guidance, adj. net revenue (high end) | D29: 4850000 | G29: Q2'26 release, p.9: $4.75bn-$4.85bn adjusted net revenue
B30: Model vs guidance | D30: =D28/D29-1 -> 0.03930545 | G30: If the model runs well above guidance, an assumption is too aggressive.
B31: Model revenue CAGR, 2025A-2028E | D31: =(F14/C14)^(1/3)-1 -> 0.30584483 | G31: Compound annual growth rate implied by the three-year forecast.
B32: Management medium-term target | D32: 0.3 | G32: Q4'25 release, p.9: at least 30% compound adj. net revenue growth, 2025 to 2028.
B33: Model vs medium-term target | D33: =D31-D32 -> 0.0058448324 | G33: Near zero = the forecast tracks management's own medium-term plan.
B35: There is no annual guidance for 2027 or 2028, management gives only a 2026 figure and a three year compound target. The CAGR test above is therefore the correct check for the later years, not a year-by-year comparison.

Sheet 4. Valuation
B2: TAB 4: VALUATION (Residual Income)
B3: A standard DCF does not work on a bank: a growing lender consumes cash, so free cash flow is negative when the business is doing well. This values the equity directly, asking whether SoFi earns more than its cost of equity on the book value it holds. Cells marked n/a are point-in-time values (a share price, a discount rate) that do not vary by forecast year, they are not missing data.
C5: As of Aug 10, 2026 | D5: 2026E | E5: 2027E | F5: 2028E | G5: Note
B6: MARKET DATA AS OF AUGUST 10, 2026
B7: Share price | C7: 18.38 | D7: n/a | E7: n/a | F7: n/a | G7: Closing price, Aug 10 2026
B8: Diluted shares outstanding (000s) | C8: 1290312 | D8: n/a | E8: n/a | F8: n/a | G8: Q2'26 release, Table 3, p.21
B9: Market capitalisation | C9: =C7*C8 -> 23715935 | D9: n/a | E9: n/a | F9: n/a | G9: Price x shares
B10: Tangible book value (current) | C10: 9470220 | D10: n/a | E10: n/a | F10: n/a | G10: Q2'26 release, p.19 (June 30, 2026)
B11: Tangible book value per share | C11: =C10/C8 -> 7.3394807 | D11: n/a | E11: n/a | F11: n/a | G11: Q2'26 book. The residual income build starts from year-end 2025 book ($6.90/share), so the residual income value is struck at 1 Jan 2026.
B12: Price / tangible book value | C12: =C7/C11 -> 2.5042644 | D12: n/a | E12: n/a | F12: n/a | G12: What the market pays per dollar of book equity
B14: COST OF EQUITY
B15: Risk-free rate | C15: ='2. Assumptions'!C15 -> 0.0469 | D15: n/a | E15: n/a | F15: n/a
B16: Equity risk premium | C16: ='2. Assumptions'!C16 -> 0.0423 | D16: n/a | E16: n/a | F16: n/a
B17: Beta | C17: ='2. Assumptions'!C17 -> 2.2 | D17: n/a | E17: n/a | F17: n/a
B18: Cost of equity | C18: ='2. Assumptions'!C18 -> 0.13996 | D18: n/a | E18: n/a | F18: n/a | G18: CAPM. For a bank, discount at cost of equity, never WACC.
B19: Terminal growth rate | C19: ='2. Assumptions'!C19 -> 0.04 | D19: n/a | E19: n/a | F19: n/a
B21: RESIDUAL INCOME
B22: Beginning tangible book value | C22: n/a | D22: 8908116 | E22: =D26 -> 9658908.9 | F22: =E26 -> 10733935 | G22: Dec 31, 2025 tangible book value, the model's starting point (Q4'25 release, p.19)
B23: Net income | C23: n/a | D23: ='3. Projections'!D19 -> 750792.87 | E23: ='3. Projections'!E19 -> 1075026.6 | F23: ='3. Projections'!F19 -> 1423451.4
B24: Equity charge (beginning TBV x cost of equity) | C24: n/a | D24: =D22*$C$18 -> 1246779.9 | E24: =E22*$C$18 -> 1351860.9 | F24: =F22*$C$18 -> 1502321.6
B25: Residual income | C25: n/a | D25: =D23-D24 -> -495987.04 | E25: =E23-E24 -> -276834.33 | F25: =F23-F24 -> -78870.182 | G25: Profit above (or below) what shareholders require. Negative = not yet earning its cost of equity.
B26: Ending tangible book value | C26: n/a | D26: =D22+D23 -> 9658908.9 | E26: =E22+E23 -> 10733935 | F26: =F22+F23 -> 12157387 | G26: No dividend, so book value grows by retained earnings. | H26: Simplification: assumes full retention with no share issuance. Share count rose 1.271bn to 1.290bn in H1 2026, so per-share book grows slower in reality.
B27: Discount period | C27: n/a | D27: 1 | E27: 2 | F27: 3
B28: Discount factor | C28: n/a | D28: =1/(1+$C$18)^D27 -> 0.87722376 | E28: =1/(1+$C$18)^E27 -> 0.76952153 | F28: =1/(1+$C$18)^F27 -> 0.67504257
B29: PV of residual income | C29: n/a | D29: =D25*D28 -> -435091.62 | E29: =E25*E28 -> -213029.98 | F29: =F25*F28 -> -53240.73
B31: TERMINAL VALUE
B32: Terminal ROTCE | C32: 0.2 | D32: n/a | E32: n/a | F32: n/a | G32: Low end of management's 20-30% long-term target. A judgment, not a derivation.
B33: Terminal residual income | C33: =F26*(C32-C18) -> 729929.51 | D33: n/a | E33: n/a | F33: n/a | G33: Ending TBV x (terminal ROTCE - cost of equity)
B34: Terminal value at end of 2028 | C34: =C33/(C18-C19) -> 7302215.9 | D34: n/a | E34: n/a | F34: n/a | G34: Perpetuity: terminal RI / (cost of equity - g)
B35: PV of terminal value | C35: =C34*F28 -> 4929306.6 | D35: n/a | E35: n/a | F35: n/a | G35: Discounted back three years
B37: VALUE PER SHARE
B38: Beginning tangible book value (Dec 2025) | C38: =D22 -> 8908116 | D38: n/a | E38: n/a | F38: n/a
B39: PV of residual income, 2026-2028 | C39: =SUM(D29:F29) -> -701362.33 | D39: n/a | E39: n/a | F39: n/a
B40: PV of terminal value | C40: =C35 -> 4929306.6 | D40: n/a | E40: n/a | F40: n/a
B41: Equity value | C41: =C38+C39+C40 -> 13136060 | D41: n/a | E41: n/a | F41: n/a
B42: Value per share | C42: =C41/C8 -> 10.18053 | D42: n/a | E42: n/a | F42: n/a
B43: Current share price | C43: =C7 -> 18.38 | D43: n/a | E43: n/a | F43: n/a
B44: Upside / (downside) | C44: =C42/C43-1 -> -0.44610826 | D44: n/a | E44: n/a | F44: n/a
B46: CROSS-CHECK: justified price / tangible book value
B47: Justified P/TBV at terminal ROTCE | C47: =(C32-C19)/(C18-C19) -> 1.6006403 | D47: n/a | E47: n/a | F47: n/a | G47: (ROTCE - g) / (cost of equity - g). The standard bank multiple formula.
...

Sheet 5. Comps - Banks
B2: BANK COMPARABLES
B3: Banks are valued on book value and returns on equity, not revenue multiples.
B4: Three metrics: what the market pays per dollar of book, what the company earns on it, and how fast it grows.
B6: Metric | C6: Ally (ALLY) | D6: Capital One (COF) | E6: Synchrony (SYF) | F6: Happen (HAPN) (ex-LendingClub) | G6: Peer median | H6: SoFi
B7: Price / tangible book value | C7: 1.0379867 | D7: 2.0697652 | E7: 1.8707451 | F7: 1.5508407 | G7: =IFERROR(MEDIAN(C7:F7),"") -> 1.7107929 | H7: ='4. Valuation'!C12 -> 2.5042644 | I7: P/TBV = price / tangible book per share. ALLY $43.72/$42.12; COF $217.76/$105.21; SYF $78.59/$42.01 (Aug 7 2026). HAPN $19.37/$12.49; cross-checks to 1.54x using Q2'26 ROTCE-derived book, so ~1.55x either way.
B8: Return on tangible common equity | C8: 0.118 | D8: 0.1804 | E8: 0.252 | F8: 0.159 | G8: =IFERROR(MEDIAN(C8:F8),"") -> 0.1697 | H8: =IFERROR('3. Projections'!D25,"") -> 0.084281892 | I8: All REPORTED, Q2'26 releases: ALLY core 11.8%; COF 18.04% (Table 15, Reconciliation of Non-GAAP Measures); SYF 25.2%; HAPN 15.9%. None derived.
B9: Revenue growth (2026E) | C9: 0.1 | D9: 0.26 | E9: 0.02 | F9: 0.116 | G9: =IFERROR(MEDIAN(C9:F9),"") -> 0.108 | H9: ='3. Projections'!D22 -> 0.39500072 | I9: Q2'26 YoY: COF total net revenue +27%; SYF revenue +2%; ALLY adj. net revenue +10%; HAPN +11.6% TTM.
B11: Implied SoFi value per share (peer median P/TBV x SoFi TBVPS) | C11: =IFERROR(G7*'4. Valuation'!C11,"") -> 12.556331
B12: Current share price | C12: ='4. Valuation'!C7 -> 18.38

Sheet 6. Comps - Fintechs
B2: FINTECH COMPARABLES
B3: Growth companies are valued on revenue multiples and margins, not book value.
B4: Three metrics: what the market pays per dollar of revenue, how fast revenue grows, and how profitable it is.
B6: Metric | C6: Block (XYZ) | D6: PayPal (PYPL) | E6: Robinhood (HOOD) | F6: Nu Holdings (NU) | G6: Peer median | H6: SoFi
B7: Price / sales (2026E) | C7: 1.8945687 | D7: 1.1117699 | E7: 17.231237 | F7: 8.8274045 | G7: =IFERROR(MEDIAN(C7:F7),"") -> 5.3609866 | H7: ='4. Valuation'!C9/'3. Projections'!D14 -> 4.7049531 | I7: P/S = market cap / TTM revenue, all stockanalysis.com Aug 10 2026. XYZ 47.44/25.04; PYPL 37.50/33.73; HOOD 84.95/4.93; NU 67.00/7.59.
B8: Revenue growth (2026E) | C8: 0.051 | D8: 0.05 | E8: 0.383 | F8: 0.345 | G8: =IFERROR(MEDIAN(C8:F8),"") -> 0.198 | H8: ='3. Projections'!D22 -> 0.39500072 | I8: Revenue growth = TTM year-over-year (YoY), same source. PYPL is Q2'26 YoY.
B9: Net income margin (TTM) | C9: 0.01426278 | D9: 0.1436 | E9: 0.4198783 | F9: 0.41897233 | G9: =IFERROR(MEDIAN(C9:F9),"") -> 0.28128617 | H9: ='3. Projections'!D23 -> 0.14894818 | I9: Net income margin replaces adj. EBITDA margin: EBITDA is not meaningful for Nu (a bank, where interest is an operating cost) and each company defines adjusted EBITDA differently. Net margin is computed the same way for all four. Source: stockanalysis.com, Aug 2026.
B11: Implied SoFi value per share (peer median P/S x SoFi revenue per share) | C11: =IFERROR(G7*('3. Projections'!D14/'4. Valuation'!C8),"") -> 20.942809
B12: Current share price | C12: ='4. Valuation'!C7 -> 18.38

Sheet 7. Sensitivity
B2: TAB 7: SENSITIVITY
B3: Value per share under different long-run ROTCE and cost of equity assumptions.
B5: Value per share = ((ROTCE - g) / (cost of equity - g)) x tangible book value per share
B7: Terminal ROTCE \ Cost of equity | C7: 0.1 | D7: 0.115 | E7: 0.128 | F7: 0.14 | G7: 0.155
B8: 0.12 | C8: =IF((C$7-'4. Valuation'!$C$19)<=0,"n/a",(($B8-'4. Valuation'!$C$19)/(C$7-'4. Valuation'!$C$19))*'4. Valuation'!$C$11) -> 9.7859742 | D8: =IF((D$7-'4. Valuation'!$C$19)<=0,"n/a",(($B8-'4. Valuation'!$C$19)/(D$7-'4. Valuation'!$C$19))*'4. Valuation'!$C$11) -> 7.8287794 | E8: =IF((E$7-'4. Valuation'!$C$19)<=0,"n/a",(($B8-'4. Valuation'!$C$19)/(E$7-'4. Valuation'!$C$19))*'4. Valuation'!$C$11) -> 6.6722552 | F8: =IF((F$7-'4. Valuation'!$C$19)<=0,"n/a",(($B8-'4. Valuation'!$C$19)/(F$7-'4. Valuation'!$C$19))*'4. Valuation'!$C$11) -> 5.8715845 | G8: =IF((G$7-'4. Valuation'!$C$19)<=0,"n/a",(($B8-'4. Valuation'!$C$19)/(G$7-'4. Valuation'!$C$19))*'4. Valuation'!$C$11) -> 5.1057257
B9: 0.16 | C9: =IF((C$7-'4. Valuation'!$C$19)<=0,"n/a",(($B9-'4. Valuation'!$C$19)/(C$7-'4. Valuation'!$C$19))*'4. Valuation'!$C$11) -> 14.678961 | D9: =IF((D$7-'4. Valuation'!$C$19)<=0,"n/a",(($B9-'4. Valuation'!$C$19)/(D$7-'4. Valuation'!$C$19))*'4. Valuation'!$C$11) -> 11.743169 | E9: =IF((E$7-'4. Valuation'!$C$19)<=0,"n/a",(($B9-'4. Valuation'!$C$19)/(E$7-'4. Valuation'!$C$19))*'4. Valuation'!$C$11) -> 10.008383 | F9: =IF((F$7-'4. Valuation'!$C$19)<=0,"n/a",(($B9-'4. Valuation'!$C$19)/(F$7-'4. Valuation'!$C$19))*'4. Valuation'!$C$11) -> 8.8073768 | G9: =IF((G$7-'4. Valuation'!$C$19)<=0,"n/a",(($B9-'4. Valuation'!$C$19)/(G$7-'4. Valuation'!$C$19))*'4. Valuation'!$C$11) -> 7.6585885
B10: 0.2 | C10: =IF((C$7-'4. Valuation'!$C$19)<=0,"n/a",(($B10-'4. Valuation'!$C$19)/(C$7-'4. Valuation'!$C$19))*'4. Valuation'!$C$11) -> 19.571948 | D10: =IF((D$7-'4. Valuation'!$C$19)<=0,"n/a",(($B10-'4. Valuation'!$C$19)/(D$7-'4. Valuation'!$C$19))*'4. Valuation'!$C$11) -> 15.657559 | E10: =IF((E$7-'4. Valuation'!$C$19)<=0,"n/a",(($B10-'4. Valuation'!$C$19)/(E$7-'4. Valuation'!$C$19))*'4. Valuation'!$C$11) -> 13.34451 | F10: =IF((F$7-'4. Valuation'!$C$19)<=0,"n/a",(($B10-'4. Valuation'!$C$19)/(F$7-'4. Valuation'!$C$19))*'4. Valuation'!$C$11) -> 11.743169 | G10: =IF((G$7-'4. Valuation'!$C$19)<=0,"n/a",(($B10-'4. Valuation'!$C$19)/(G$7-'4. Valuation'!$C$19))*'4. Valuation'!$C$11) -> 10.211451
B11: 0.24 | C11: =IF((C$7-'4. Valuation'!$C$19)<=0,"n/a",(($B11-'4. Valuation'!$C$19)/(C$7-'4. Valuation'!$C$19))*'4. Valuation'!$C$11) -> 24.464936 | D11: =IF((D$7-'4. Valuation'!$C$19)<=0,"n/a",(($B11-'4. Valuation'!$C$19)/(D$7-'4. Valuation'!$C$19))*'4. Valuation'!$C$11) -> 19.571948 | E11: =IF((E$7-'4. Valuation'!$C$19)<=0,"n/a",(($B11-'4. Valuation'!$C$19)/(E$7-'4. Valuation'!$C$19))*'4. Valuation'!$C$11) -> 16.680638 | F11: =IF((F$7-'4. Valuation'!$C$19)<=0,"n/a",(($B11-'4. Valuation'!$C$19)/(F$7-'4. Valuation'!$C$19))*'4. Valuation'!$C$11) -> 14.678961 | G11: =IF((G$7-'4. Valuation'!$C$19)<=0,"n/a",(($B11-'4. Valuation'!$C$19)/(G$7-'4. Valuation'!$C$19))*'4. Valuation'!$C$11) -> 12.764314
B12: 0.28 | C12: =IF((C$7-'4. Valuation'!$C$19)<=0,"n/a",(($B12-'4. Valuation'!$C$19)/(C$7-'4. Valuation'!$C$19))*'4. Valuation'!$C$11) -> 29.357923 | D12: =IF((D$7-'4. Valuation'!$C$19)<=0,"n/a",(($B12-'4. Valuation'!$C$19)/(D$7-'4. Valuation'!$C$19))*'4. Valuation'!$C$11) -> 23.486338 | E12: =IF((E$7-'4. Valuation'!$C$19)<=0,"n/a",(($B12-'4. Valuation'!$C$19)/(E$7-'4. Valuation'!$C$19))*'4. Valuation'!$C$11) -> 20.016766 | F12: =IF((F$7-'4. Valuation'!$C$19)<=0,"n/a",(($B12-'4. Valuation'!$C$19)/(F$7-'4. Valuation'!$C$19))*'4. Valuation'!$C$11) -> 17.614754 | G12: =IF((G$7-'4. Valuation'!$C$19)<=0,"n/a",(($B12-'4. Valuation'!$C$19)/(G$7-'4. Valuation'!$C$19))*'4. Valuation'!$C$11) -> 15.317177
B13: 0.32 | C13: =IF((C$7-'4. Valuation'!$C$19)<=0,"n/a",(($B13-'4. Valuation'!$C$19)/(C$7-'4. Valuation'!$C$19))*'4. Valuation'!$C$11) -> 34.25091 | D13: =IF((D$7-'4. Valuation'!$C$19)<=0,"n/a",(($B13-'4. Valuation'!$C$19)/(D$7-'4. Valuation'!$C$19))*'4. Valuation'!$C$11) -> 27.400728 | E13: =IF((E$7-'4. Valuation'!$C$19)<=0,"n/a",(($B13-'4. Valuation'!$C$19)/(E$7-'4. Valuation'!$C$19))*'4. Valuation'!$C$11) -> 23.352893 | F13: =IF((F$7-'4. Valuation'!$C$19)<=0,"n/a",(($B13-'4. Valuation'!$C$19)/(F$7-'4. Valuation'!$C$19))*'4. Valuation'!$C$11) -> 20.550546 | G13: =IF((G$7-'4. Valuation'!$C$19)<=0,"n/a",(($B13-'4. Valuation'!$C$19)/(G$7-'4. Valuation'!$C$19))*'4. Valuation'!$C$11) -> 17.87004
B15: Current share price | C15: ='4. Valuation'!C7 -> 18.38 | H15: The model's cost of equity is 14.00% (beta 2.20)
B16: Base case value per share | C16: ='4. Valuation'!C42 -> 10.18053 | H16: At 20% terminal ROTCE and 14.00% cost of equity, the grid gives $11.74; the full residual income model gives $10.18.
B18: How to read this: cost of equity across the top, long-run ROTCE down the side. Cells above the current share price imply upside.
B21: THE TWO LENSES: this is the answer to the question
B22: The bank versus fintech question is not rhetorical: it is the beta. A bank's cost of equity is low, so its future profits are worth more today; a fintech's is high, so the same profits are worth less.
C24: Bank lens | D24: Fintech lens
B25: Beta assumption | C25: 1.2 | D25: 2.2
B26: Cost of equity | C26: ='2. Assumptions'!C15+C25*'2. Assumptions'!C16 -> 0.09766 | D26: ='2. Assumptions'!C15+D25*'2. Assumptions'!C16 -> 0.13996
B27: Terminal ROTCE | C27: 0.2 | D27: 0.2
B28: Justified P/TBV | C28: =(C27-'2. Assumptions'!C19)/(C26-'2. Assumptions'!C19) -> 2.7748873 | D28: =(D27-'2. Assumptions'!C19)/(D26-'2. Assumptions'!C19) -> 1.6006403
B29: Value per share | C29: =C28*'4. Valuation'!C11 -> 20.366232 | D29: =D28*'4. Valuation'!C11 -> 11.747868
B30: Current share price | C30: ='4. Valuation'!C7 -> 18.38 | D30: ='4. Valuation'!C7 -> 18.38
B31: Upside / (downside) | C31: =C29/C30-1 -> 0.10806483 | D31: =D29/D30-1 -> -0.36083415
B32: Read this way: if SoFi is a bank, its cost of equity should look like a bank's (1.2 beta) and the stock is roughly fairly valued. If it is a high-beta growth fintech, its observed 2.2 beta applies and the stock is worth about half the market price. The full residual income model on Tab 4 gives $19.77 and $10.18 respectively, same conclusion, small method difference.
B36: SCENARIO ANALYSIS: bear / base / bull
B37: Each case changes three things together: how risky the market judges SoFi (beta), how profitable it becomes long term (terminal ROTCE), and whether execution beats or misses my base forecast.
C39: Bear | D39: Base | E39: Bull
B40: Beta | C40: 2.6 | D40: 2.2 | E40: 1.4
B41: Cost of equity | C41: ='2. Assumptions'!C15+C40*'2. Assumptions'!C16 -> 0.15688 | D41: ='2. Assumptions'!C15+D40*'2. Assumptions'!C16 -> 0.13996 | E41: ='2. Assumptions'!C15+E40*'2. Assumptions'!C16 -> 0.10612
B42: Terminal ROTCE | C42: 0.14 | D42: 0.2 | E42: 0.26
B43: Terminal growth | C43: 0.035 | D43: 0.04 | E43: 0.045
B44: Net income vs base forecast | C44: 0.85 | D44: 1 | E44: 1.15
B45: Value per share | C45: 5.03 | D45: 10.18 | E45: 25.47
B46: Current share price | C46: ='4. Valuation'!C7 -> 18.38 | D46: ='4. Valuation'!C7 -> 18.38 | E46: ='4. Valuation'!C7 -> 18.38 | G46: Value per share is the full residual income model re-run under each case, not a shortcut formula. To reproduce: set beta and terminal ROTCE on Tab 2 / Tab 4 and read Tab 4 value per share.
B47: Upside / (downside) | C47: =C45/C46-1 -> -0.72633297 | D47: =D45/D46-1 -> -0.44613711 | E47: =E45/E46-1 -> 0.38574538
B49: WHAT EACH CASE ASSUMES
B50: Bear | C50: Deposit competition intensifies and rate cuts resume, compressing margin. Expense growth stays at H1's 33% as new-product investment continues without payback. SoFi stays classified as a high-beta fintech. Long-run ROTCE settles at 14%, below every bank peer except Ally.
B51: Base | C51: Management delivers its stated plan: ~30% revenue CAGR to 2028, margin near 5.95%, expenses decelerating below revenue. Long-run ROTCE reaches the low end of the 20-30% target. Beta stays where the market currently prices it.
B52: Bull | C52: The Loan Platform Business scales, generating fee income without consuming balance sheet, so returns rise on a smaller equity base. Operating leverage lands early and the 25-30% net income margin target is hit by 2028. As the deposit franchise matures, beta compresses toward bank peers and the discount rate falls, the single biggest driver of the upside.
B54: The spread from $5.03 to $25.47 is driven mainly by beta, not by operating performance. That is the point of the thesis: the classification question is worth more than the execution question.
